const catchAsyncErrors = (fn) => (req, res, next) => {
  Promise.resolve(fn(req, res, next)).catch(next);
};

const errorHandler = (err, req, res, next) => {
  console.error(err.stack);
  res.status(err.statusCode || 500).json({
    success: false,
    message: err.message || "Internal Server Error",
  });
};

module.exports = {
  catchAsyncErrors,
  errorHandler,
};
